<?xml version="1.0"?>

<robot xmlns:xacro="http://ros.org/wiki/xacro" xmlns:gz="http://gazebosim.org/schema">

  <xacro:property name="mu1" value="1.0" />
  <xacro:property name="mu2" value="0.0" />

  <xacro:macro name="mecanum_wheel" params="name parent *origin side">

    <link name="${name}_link">
      <inertial>
        <origin xyz="0 0 0" rpy="0 0 0" />
        <mass value="0.6" />
        <inertia ixx="0.02" iyy="0.02" izz="0.02" ixy="0.00" ixz="0.00" iyz="0.00" />
      </inertial>
      <visual>
        <origin rpy="0 0 0" xyz="0 0 0" />
        <geometry>
          <mesh filename="package://agrobot_urdf/meshes/mecanum_wheel/mecanum_wheel_${side}.obj"
            scale="1 1 1" />
        </geometry>
      </visual>
      <collision>
        <origin rpy="0 0 0" xyz="0 0 0" />
        <geometry>
          <mesh filename="package://agrobot_urdf/meshes/mecanum_wheel/mecanum_wheel_${side}.obj"
            scale="1 1 1" />
        </geometry>
      </collision>
    </link>

    <joint name="${name}_joint" type="continuous">
      <xacro:insert_block name="origin" />
      <parent link="${parent}" />
      <child link="${name}_link" />
      <axis xyz="0 0 1" />
    </joint>

    <gazebo reference="${name}_link">
      <collision>
        <surface>
          <friction>
            <ode>
              <mu>${mu1}
              </mu>
              <mu2>${mu2}</mu2>
              <xacro:if value="${side == 'right'}">
                <fdir1 gz:expressed_in="base_footprint">1 1 0</fdir1>
              </xacro:if>
              <xacro:if value="${side == 'left'}">
                <fdir1 gz:expressed_in="base_footprint">1 -1 0</fdir1>
              </xacro:if>
            </ode>
          </friction>
        </surface>
      </collision>
    </gazebo>

  </xacro:macro>

</robot>
